Workbook

Sheet Data
A1: Customer ID | B1: Gender | C1: Product_Category | D1: Customer_Segment | E1: Payment_Method | F1: Region | G1: City | H1: Sales_Channel | I1: Order_Status | J1: Sales | K1: Quantity Sold | L1: Discount Rate | M1: Delivery_Days | N1: Profit Margin
A2: 2 | B2: Female | C2: Clothing | D2: Wholesale | E2: Cash | F2: West | G2: Phoenix | H2: Catalog | I2: Cancelled | J2: 886.13398 | K2: 22.670661 | L2: 0.099897857 | M2: 2.2397971 | N2: 0.220737
A3: 4 | B3: Female | C3: Beauty & Health | D3: Business | E3: Credit Card | F3: East | G3: San Diego | H3: Catalog | I3: Cancelled | J3: 610.02358 | K3: 22.712923 | L3: 0.18491416 | M3: 4.7441648 | N3: 0.30629011
A4: 6 | B4: Female | C4: Home & Kitchen | D4: Business | E4: Cash | F4: East | G4: Chicago | H4: Online | I4: Completed | J4: 576.61392 | K4: 32.112951 | L4: 0.17917733 | M4: 4.5020717 | N4: 0.2921224
A5: 8 | B5: Female | C5: Home & Kitchen | D5: Wholesale | E5: PayPal | F5: East | G5: San Diego | H5: Online | I5: Cancelled | J5: 372.90517 | K5: 32.509504 | L5: 0.099897857 | M5: 2.1554926 | N5: 0.21104944
A6: 10 | B6: Female | C6: Clothing | D6: Individual | E6: Bank Transfer | F6: North | G6: Phoenix | H6: Catalog | I6: Returned | J6: 413.90525 | K6: 22.800457 | L6: 0.099897857 | M6: 2.391061 | N6: 0.22284298
A7: 12 | B7: Female | C7: Electronics | D7: Wholesale | E7: Cash | F7: West | G7: Chicago | H7: Phone | I7: Completed | J7: 726.81694 | K7: 34.16821 | L7: 0.25577788 | M7: 7.2391498 | N7: 0.3515502
A8: 14 | B8: Female | C8: Electronics | D8: Business | E8: Credit Card | F8: West | G8: Dallas | H8: Online | I8: Cancelled | J8: 497.81318 | K8: 34.233543 | L8: 0.18100318 | M8: 2.2397971 | N8: 0.26802295
A9: 16 | B9: Female | C9: Electronics | D9: Business | E9: Credit Card | F9: East | G9: Los Angeles | H9: Phone | I9: Returned | J9: 610.02358 | K9: 42.863547 | L9: 0.30486451 | M9: 8.5106817 | N9: 0.40987566
A10: 18 | B10: Female | C10: Home & Kitchen | D10: Business | E10: PayPal | F10: North | G10: San Diego | H10: Catalog | I10: Pending | J10: 291.05761 | K10: 19.701526 | L10: 0.07300551 | M10: 2.391061 | N10: 0.1771287
A11: 20 | B11: Female | C11: Sports & Outdoors | D11: Wholesale | E11: PayPal | F11: North | G11: Philadelphia | H11: Online | I11: Pending | J11: 551.575 | K11: 42.328425 | L11: 0.24983818 | M11: 6.4350845 | N11: 0.34135722
A12: 22 | B12: Female | C12: Home & Kitchen | D12: Wholesale | E12: PayPal | F12: South | G12: Chicago | H12: Online | I12: Completed | J12: 252.88053 | K12: 32.124851 | L12: 0.070450973 | M12: 1 | N12: 0.14962905
A13: 24 | B13: Female | C13: Sports & Outdoors | D13: Business | E13: Credit Card | F13: South | G13: New York | H13: Online | I13: Pending | J13: 521.92242 | K13: 27.640041 | L13: 0.1847924 | M13: 3.9722662 | N13: 0.2736767
... A101: 99 | B101: Male | C101: Sports & Outdoors | D101: Business | E101: Bank Transfer | F101: South | G101: San Diego | H101: Catalog | I101: Returned | J101: 504.65459 | K101: 25.659829 | L101: 0.18251118 | M101: 2.9295154 | N101: 0.26928535

Sheet Sheet2
A1: This Year PM | B1: Previous Year PM | D1: Question
A2: 0.28936177 | B2: 0.20125924 | D2: Is there any significant difference in the average profit margin between this year and previous year ?
A3: 0.220737 | B3: 0.28254163
A4: 0.25439927 | B4: 0.18854602 | M4: Sig Level | N4: 0.05
A5: 0.30629011 | B5: 0.11917017
A6: 0.21021883 | B6: 0.12269902 | M6: t-Test: Paired Two Sample for Means
A7: 0.2921224 | B7: 0.18529426
A8: 0.31072854 | B8: 0.21503938 | N8: This Year PM | O8: Previous Year PM
A9: 0.21104944 | B9: 0.41531825 | M9: Mean | N9: 0.28688022 | O9: 0.20712816
A10: 0.27918052 | B10: 0.1171005 | M10: Variance | N10: 0.0038774453 | O10: 0.0099798048
A11: 0.22284298 | B11: 0.11727691 | M11: Observations | N11: 100 | O11: 100
A12: 0.29895453 | B12: 0.078581139 | M12: Pearson Correlation | N12: 0.1295224
A13: 0.3515502 | B13: 0.38761708 | M13: Hypothesized Mean Difference | N13: 0
A14: 0.25465479 | B14: 0.33054788 | M14: df | N14: 99
A15: 0.26802295 | B15: 0.29504238 | M15: t Stat | N15: 7.2068884
A16: 0.35719493 | B16: 0.20125924 | M16: P(T<=t) one-tail | N16: 5.7416398e-11
A17: 0.40987566 | B17: 0.28254163 | M17: t Critical one-tail | N17: 1.6603912
A18: 0.31830109 | B18: 0.18854602 | M18: P(T<=t) two-tail | N18: 1.148328e-10
A19: 0.1771287 | B19: 0.11917017 | M19: t Critical two-tail | N19: 1.984217
A20: 0.28515499 | B20: 0.21503938
A21: 0.34135722 | B21: 0.41531825
A22: 0.25651376 | B22: 0.1171005 | M22: P is Lower than Sig level; the rejecting Null hypo, accepting alternative hypo; there is a significant difference
A23: 0.14962905 | B23: 0.11727691
A24: 0.18294063 | B24: 0.078581139
A25: 0.2736767 | B25: 0.18698569
A26: 0.22479924 | B26: 0.28576596
A27: 0.25128815 | B27: 0.29751197
A28: 0.34981256 | B28: 0.31794401
A29: 0.2756871 | B29: 0.28723206
A30: 0.29108656 | B30: 0.31581109
A31: 0.25301998 | B31: 0.11817793
A32: 0.28087419 | B32: 0.018686547
A33: 0.29589157 | B33: 0.18912399
A34: 0.35610875 | B34: 0.055191566
... A101: 0.23183288 | B101: 0.22320499

Sheet ANOVA
A1: =[1]Data!F1 -> Region | B1: =[1]Data!J1 -> Sales
A2: =[1]Data!F5 -> East | B2: =[1]Data!J5 -> 610.02358 | D2: Is there any sig difference among the major region? | O2: Anova: Single Factor
A3: =[1]Data!F6 -> East | B3: =[1]Data!J6 -> 364.77613
A4: =[1]Data!F7 -> East | B4: =[1]Data!J7 -> 576.61392 | K4: Row Labels | L4: Count of Region | O4: SUMMARY
A5: =[1]Data!F9 -> East | B5: =[1]Data!J9 -> 372.90517 | K5: East | L5: 23 | O5: Groups | P5: Count | Q5: Sum | R5: Average | S5: Variance
A6: =[1]Data!F12 -> East | B6: =[1]Data!J12 -> 600.05115 | K6: North | L6: 29 | O6: EAST | P6: 23 | Q6: 11456.662 | R6: 498.11575 | S6: 17935.219
A7: =[1]Data!F17 -> East | B7: =[1]Data!J17 -> 610.02358 | K7: South | L7: 29 | O7: NORTH | P7: 29 | Q7: 15231.224 | R7: 525.21461 | S7: 19954.872
A8: =[1]Data!F26 -> East | B8: =[1]Data!J26 -> 415.68002 | K8: West | L8: 19 | O8: SOUTH | P8: 29 | Q8: 16043.292 | R8: 553.21695 | S8: 28454.57
A9: =[1]Data!F31 -> East | B9: =[1]Data!J31 -> 473.55217 | K9: Grand Total | L9: 100 | O9: WEST | P9: 19 | Q9: 10795.751 | R9: 568.19741 | S9: 36899.964
A10: =[1]Data!F35 -> East | B10: =[1]Data!J35 -> 830.1337
A11: =[1]Data!F36 -> East | B11: =[1]Data!J36 -> 307.91532
A12: =[1]Data!F38 -> East | B12: =[1]Data!J38 -> 449.13093 | K12: EAST | L12: NORTH | M12: SOUTH | N12: WEST | O12: ANOVA
A13: =[1]Data!F46 -> East | B13: =[1]Data!J46 -> 291.05761 | K13: 610.02358 | L13: 449.13093 | M13: 619.41734 | N13: 886.13398 | O13: Source of Variation | P13: SS | Q13: df | R13: MS | S13: F | T13: P-value | U13: F crit
A14: =[1]Data!F50 -> East | B14: =[1]Data!J50 -> 606.72438 | K14: 364.77613 | L14: 545.77267 | M14: 449.13093 | N14: 726.81694 | O14: Between Groups | P14: 64623.064 | Q14: 3 | R14: 21541.021 | S14: 0.85655912 | T14: 0.46649917 | U14: 2.6993926
A15: =[1]Data!F51 -> East | B15: =[1]Data!J51 -> 484.28885 | K15: 576.61392 | L15: 413.90525 | M15: 696.8107 | N15: 497.81318 | O15: Within Groups | P15: 2414238.6 | Q15: 96 | R15: 25148.318
A16: =[1]Data!F61 -> East | B16: =[1]Data!J61 -> 504.65459 | K16: 372.90517 | L16: 491.90098 | M16: 252.88053 | N16: 734.5436
A17: =[1]Data!F62 -> East | B17: =[1]Data!J62 -> 319.56345 | K17: 600.05115 | L17: 614.24978 | M17: 521.92242 | N17: 720.9101 | O17: Total | P17: 2478861.6 | Q17: 99
A18: =[1]Data!F63 -> East | B18: =[1]Data!J63 -> 619.41734 | K18: 610.02358 | L18: 291.05761 | M18: 463.17255 | N18: 610.02358
A19: =[1]Data!F65 -> East | B19: =[1]Data!J65 -> 521.92242 | K19: 415.68002 | L19: 551.575 | M19: 573.45235 | N19: 890.46319
A20: =[1]Data!F67 -> East | B20: =[1]Data!J67 -> 619.41734 | K20: 473.55217 | L20: 495.58883 | M20: 545.77267 | N20: 421.88564
A21: =[1]Data!F75 -> East | B21: =[1]Data!J75 -> 551.575 | K21: 830.1337 | L21: 294.05947 | M21: 375.22752 | N21: 559.97758
A22: =[1]Data!F88 -> East | B22: =[1]Data!J88 -> 518.08896 | K22: 307.91532 | L22: 830.1337 | M22: 708.16776 | N22: 305.47025 | P22: Average Sale
A23: =[1]Data!F92 -> East | B23: =[1]Data!J92 -> 291.05761 | K23: 449.13093 | L23: 557.79181 | M23: 503.26712 | N23: 659.36358 | P23: EAST | Q23: =AVERAGE(K13:K35) -> 498.11575
A24: =[1]Data!F96 -> East | B24: =[1]Data!J96 -> 518.08896 | K24: 291.05761 | L24: 734.5436 | M24: 696.8107 | N24: 581.24125 | P24: NORTH | Q24: =AVERAGE(L13:L41) -> 525.21461
A25: =[1]Data!F8 -> North | B25: =[1]Data!J8 -> 449.13093 | K25: 606.72438 | L25: 252.88053 | M25: 504.65459 | N25: 252.88053 | P25: SOUTH | Q25: =AVERAGE(M13:M41) -> 553.21695
A26: =[1]Data!F10 -> North | B26: =[1]Data!J10 -> 545.77267 | K26: 484.28885 | L26: 447.27849 | M26: 523.01127 | N26: 773.23783 | P26: WEST | Q26: =AVERAGE(N13:N31) -> 568.19741
A27: =[1]Data!F11 -> North | B27: =[1]Data!J11 -> 413.90525 | K27: 504.65459 | L27: 596.96016 | M27: 438.67525 | N27: 603.45496
A28: =[1]Data!F14 -> North | B28: =[1]Data!J14 -> 491.90098 | K28: 319.56345 | L28: 496.06703 | M28: 830.1337 | N28: 307.91532
A29: =[1]Data!F18 -> North | B29: =[1]Data!J18 -> 614.24978 | K29: 619.41734 | L29: 569.03681 | M29: 497.81318 | N29: 389.38711
A30: =[1]Data!F19 -> North | B30: =[1]Data!J19 -> 291.05761 | K30: 521.92242 | L30: 375.22752 | M30: 523.01127 | N30: 454.85169
A31: =[1]Data!F21 -> North | B31: =[1]Data!J21 -> 551.575 | K31: 619.41734 | L31: 648.04279 | M31: 473.37923 | N31: 419.38043
A32: =[1]Data!F22 -> North | B32: =[1]Data!J22 -> 495.58883 | K32: 551.575 | L32: 573.24211 | M32: 608.03537
A33: =[1]Data!F24 -> North | B33: =[1]Data!J24 -> 294.05947 | K33: 518.08896 | L33: 551.575 | M33: 362.0807
A34: =[1]Data!F29 -> North | B34: =[1]Data!J29 -> 830.1337 | K34: 291.05761 | L34: 545.77267 | M34: 726.81694
A35: =[1]Data!F37 -> North | B35: =[1]Data!J37 -> 557.79181 | K35: 518.08896 | L35: 403.40832 | M35: 886.13398
A36: =[1]Data!F39 -> North | B36: =[1]Data!J39 -> 734.5436 | L36: 886.13398 | M36: 664.15566
A37: =[1]Data!F40 -> North | B37: =[1]Data!J40 -> 252.88053 | L37: 558.4248 | M37: 817.88057
A38: =[1]Data!F42 -> North | B38: =[1]Data!J42 -> 447.27849 | L38: 569.03681 | M38: 375.22752
A39: =[1]Data!F47 -> North | B39: =[1]Data!J47 -> 596.96016 | L39: 519.22626 | M39: 167.05153
A40: =[1]Data!F53 -> North | B40: =[1]Data!J53 -> 496.06703 | L40: 521.92242 | M40: 734.5436
...

Sheet correlation
A1: =[2]Data!K1 -> Quantity Sold | B1: =[2]Data!J1 -> Sales
A2: =[2]Data!K2 -> 36.148044 | B2: =[2]Data!J2 -> 619.41734 | D2: Is there any significant differences between the variable
A3: =[2]Data!K3 -> 22.670661 | B3: =[2]Data!J3 -> 886.13398
A4: =[2]Data!K4 -> 25.659829 | B4: =[2]Data!J4 -> 449.13093
A5: =[2]Data!K5 -> 22.712923 | B5: =[2]Data!J5 -> 610.02358
A6: =[2]Data!K6 -> 22.179177 | B6: =[2]Data!J6 -> 364.77613
A7: =[2]Data!K7 -> 32.112951 | B7: =[2]Data!J7 -> 576.61392
A8: =[2]Data!K8 -> 34.16821 | B8: =[2]Data!J8 -> 449.13093
A9: =[2]Data!K9 -> 32.509504 | B9: =[2]Data!J9 -> 372.90517
A10: =[2]Data!K10 -> 28.966599 | B10: =[2]Data!J10 -> 545.77267
A11: =[2]Data!K11 -> 22.800457 | B11: =[2]Data!J11 -> 413.90525
A12: =[2]Data!K12 -> 37.920199 | B12: =[2]Data!J12 -> 600.05115
A13: =[2]Data!K13 -> 34.16821 | B13: =[2]Data!J13 -> 726.81694
A14: =[2]Data!K14 -> 34.509555 | B14: =[2]Data!J14 -> 491.90098
... A18: =[2]Data!K18 -> 34.481965 | B18: =[2]Data!J18 -> 614.24978
A19: =[2]Data!K19 -> 19.701526 | B19: =[2]Data!J19 -> 291.05761 | L19: Quantity Sold | M19: Sales | O19: P value = | P19: =P25 -> 0.0258852 | Q19: There is a significant differences
A20: =[2]Data!K20 -> 30.212204 | B20: =[2]Data!J20 -> 696.8107 | K20: Quantity Sold | L20: 1
A21: =[2]Data!K21 -> 42.328425 | B21: =[2]Data!J21 -> 551.575 | K21: Sales | L21: 0.22278596 | M21: 1 | O21: df | P21: =COUNT(B2:B101)-2 -> 98
A22: =[2]Data!K22 -> 25.761026 | B22: =[2]Data!J22 -> 495.58883
A23: =[2]Data!K23 -> 32.124851 | B23: =[2]Data!J23 -> 252.88053 | O23: t | P23: =L24 * SQRT((P21)/(1-L24^2)) -> 2.2623267
A24: =[2]Data!K24 -> 42.450393 | B24: =[2]Data!J24 -> 294.05947 | K24: Correlation (r) | L24: =L21 -> 0.22278596
A25: =[2]Data!K25 -> 27.640041 | B25: =[2]Data!J25 -> 521.92242 | O25: P value | P25: =_xlfn.T.DIST.2T(P23,P21) -> 0.0258852
A26: =[2]Data!K26 -> 23.105048 | B26: =[2]Data!J26 -> 415.68002
A27: =[2]Data!K27 -> 25.06958 | B27: =[2]Data!J27 -> 463.17255
A28: =[2]Data!K28 -> 37.446775 | B28: =[2]Data!J28 -> 720.9101
A29: =[2]Data!K29 -> 34.093862 | B29: =[2]Data!J29 -> 830.1337
A30: =[2]Data!K30 -> 31.988254 | B30: =[2]Data!J30 -> 573.45235
A31: =[2]Data!K31 -> 25.403001 | B31: =[2]Data!J31 -> 473.55217
A32: =[2]Data!K32 -> 42.957475 | B32: =[2]Data!J32 -> 545.77267
A33: =[2]Data!K33 -> 32.509504 | B33: =[2]Data!J33 -> 375.22752
A34: =[2]Data!K34 -> 37.920199 | B34: =[2]Data!J34 -> 610.02358
A35: =[2]Data!K35 -> 23.331898 | B35: =[2]Data!J35 -> 830.1337
A36: =[2]Data!K36 -> 28.213311 | B36: =[2]Data!J36 -> 307.91532
A37: =[2]Data!K37 -> 29.545056 | B37: =[2]Data!J37 -> 557.79181
... A101: =[2]Data!K101 -> 36.139059 | B101: =[2]Data!J101 -> 419.38043

Sheet pivot table
A1: Find the average discount rate, profit margin for each product
C3: Column Labels
B4: Values | C4: Beauty & Health | D4: Clothing | E4: Electronics | F4: Home & Kitchen | G4: Sports & Outdoors | H4: Grand Total
B5: Profit_Margin | C5: 0.30463161 | D5: 0.28207027 | E5: 0.29341221 | F5: 0.27348353 | G5: 0.27960911 | H5: 0.28688022
B6: Discount_Rate | C6: 0.19793081 | D6: 0.17921197 | E6: 0.19143676 | F6: 0.16045405 | G6: 0.17634524 | H6: 0.18142184
A9: Find the average sale, and quantity sold by region for each category | F9: Find the total number of product sold from each product category to different customer segment
B11: Row Labels | C11: Average of Sales | D11: Average of Quantity Sold | F11: Count of Customer_Segment | G11: Column Labels
B12: Beauty & Health | C12: 578.37358 | D12: 32.31089 | F12: Row Labels | G12: Business | H12: Individual | I12: Wholesale | J12: Grand Total
B13: East | C13: 589.28829 | D13: 28.732589 | F13: Beauty & Health | G13: 5 | H13: 8 | I13: 7 | J13: 20
B14: North | C14: 610.05442 | D14: 34.636764 | F14: Clothing | G14: 2 | H14: 7 | I14: 7 | J14: 16
B15: South | C15: 617.03483 | D15: 34.687413 | F15: Electronics | G15: 7 | H15: 8 | I15: 7 | J15: 22
B16: West | C16: 426.42029 | D16: 30.837992 | F16: Home & Kitchen | G16: 7 | H16: 3 | I16: 9 | J16: 19
B17: Clothing | C17: 524.44338 | D17: 29.735904 | F17: Sports & Outdoors | G17: 10 | H17: 5 | I17: 8 | J17: 23
B18: East | C18: 364.96997 | D18: 31.915471 | F18: Grand Total | G18: 31 | H18: 31 | I18: 38 | J18: 100
B19: North | C19: 483.22889 | D19: 29.419468
B20: South | C20: 579.92821 | D20: 30.783373
B21: West | C21: 640.08171 | D21: 27.449307 | F21: Find the total amount of revenue generated from each product category to different customer segments
B22: Electronics | C22: 541.44771 | D22: 32.717721
B23: East | C23: 494.18401 | D23: 34.852148 | F23: Sum of Sales | G23: Column Labels
B24: North | C24: 561.32432 | D24: 32.005509 | F24: Row Labels | G24: Business | H24: Individual | I24: Wholesale | J24: Grand Total
B25: South | C25: 515.30453 | D25: 29.082502 | F25: Beauty & Health | G25: 2986.3771 | H25: 4932.1077 | I25: 3648.9868 | J25: 11567.472
B26: West | C26: 589.27508 | D26: 33.891774 | F26: Clothing | G26: 1054.107 | H26: 3590.374 | I26: 3746.613 | J26: 8391.094
B27: Home & Kitchen | C27: 519.44244 | D27: 32.597943 | F27: Electronics | G27: 3275.2098 | H27: 3896.43 | I27: 4740.2096 | J27: 11911.85
B28: East | C28: 486.97261 | D28: 32.421431 | F28: Home & Kitchen | G28: 3153.8403 | H28: 1468.5473 | I28: 5247.0187 | J28: 9869.4063
B29: North | C29: 471.7979 | D29: 30.74044 | F29: Sports & Outdoors | G29: 4965.8132 | H29: 2360.5178 | I29: 4460.7757 | J29: 11787.107
B30: South | C30: 595.72531 | D30: 33.125312 | F30: Grand Total | G30: 15435.347 | H30: 16247.977 | I30: 21843.604 | J30: 53526.928
B31: West | C31: 514.702 | D31: 37.029629
B32: Sports & Outdoors | C32: 512.4829 | D32: 30.207728
B33: East | C33: 475.35181 | D33: 34.684569
B34: North | C34: 520.96917 | D34: 30.126044
B35: South | C35: 483.8119 | D35: 27.800734
B36: West | C36: 600.61116 | D36: 32.394588
B37: Grand Total | C37: 535.26928 | D37: 31.559208

Sheet pivot table chart
A2: Find the average discount rate, profit margin for each product | I2: Find the average sale, and quantity sold by region for each product category
A20: Find the total number of product sold from each product category to different customer segment

Sheet dashboard

Sheet Linear regression
A1: =[3]Data!J1 -> Sales | B1: =[3]Data!K1 -> Quantity Sold | C1: =[3]Data!N1 -> Profit Margin
A2: =[3]Data!J2 -> 619.41734 | B2: =[3]Data!K2 -> 36.148044 | C2: =[3]Data!N2 -> 0.28936177 | E2: Is there a any significant influnces of sales and quantity sold on profit margin | O2: Sig level | P2: 0.1
A3: =[3]Data!J3 -> 886.13398 | B3: =[3]Data!K3 -> 22.670661 | C3: =[3]Data!N3 -> 0.220737 | M3: SUMMARY OUTPUT
A4: =[3]Data!J4 -> 449.13093 | B4: =[3]Data!K4 -> 25.659829 | C4: =[3]Data!N4 -> 0.25439927
A5: =[3]Data!J5 -> 610.02358 | B5: =[3]Data!K5 -> 22.712923 | C5: =[3]Data!N5 -> 0.30629011 | M5: Regression Statistics
A6: =[3]Data!J6 -> 364.77613 | B6: =[3]Data!K6 -> 22.179177 | C6: =[3]Data!N6 -> 0.21021883 | M6: Multiple R | N6: 0.64905613
A7: =[3]Data!J7 -> 576.61392 | B7: =[3]Data!K7 -> 32.112951 | C7: =[3]Data!N7 -> 0.2921224 | M7: R Square | N7: 0.42127386
A8: =[3]Data!J8 -> 449.13093 | B8: =[3]Data!K8 -> 34.16821 | C8: =[3]Data!N8 -> 0.31072854 | M8: Adjusted R Square | N8: 0.40934137
A9: =[3]Data!J9 -> 372.90517 | B9: =[3]Data!K9 -> 32.509504 | C9: =[3]Data!N9 -> 0.21104944 | M9: Standard Error | N9: 0.04785652
A10: =[3]Data!J10 -> 545.77267 | B10: =[3]Data!K10 -> 28.966599 | C10: =[3]Data!N10 -> 0.27918052 | M10: Observations | N10: 100
A11: =[3]Data!J11 -> 413.90525 | B11: =[3]Data!K11 -> 22.800457 | C11: =[3]Data!N11 -> 0.22284298
A12: =[3]Data!J12 -> 600.05115 | B12: =[3]Data!K12 -> 37.920199 | C12: =[3]Data!N12 -> 0.29895453 | M12: ANOVA
A13: =[3]Data!J13 -> 726.81694 | B13: =[3]Data!K13 -> 34.16821 | C13: =[3]Data!N13 -> 0.3515502 | N13: df | O13: SS | P13: MS | Q13: F | R13: Significance F
A14: =[3]Data!J14 -> 491.90098 | B14: =[3]Data!K14 -> 34.509555 | C14: =[3]Data!N14 -> 0.25465479 | M14: Regression | N14: 2 | O14: 0.16171317 | P14: 0.080856585 | Q14: 35.304752 | R14: 3.0195703e-12
A15: =[3]Data!J15 -> 497.81318 | B15: =[3]Data!K15 -> 34.233543 | C15: =[3]Data!N15 -> 0.26802295 | M15: Residual | N15: 97 | O15: 0.22215391 | P15: 0.0022902465
A16: =[3]Data!J16 -> 734.5436 | B16: =[3]Data!K16 -> 38.910186 | C16: =[3]Data!N16 -> 0.35719493 | M16: Total | N16: 99 | O16: 0.38386708
A17: =[3]Data!J17 -> 610.02358 | B17: =[3]Data!K17 -> 42.863547 | C17: =[3]Data!N17 -> 0.40987566
A18: =[3]Data!J18 -> 614.24978 | B18: =[3]Data!K18 -> 34.481965 | C18: =[3]Data!N18 -> 0.31830109 | N18: Coefficients | O18: Standard Error | P18: t Stat | Q18: P-value | R18: Lower 95% | S18: Upper 95% | T18: Lower 90.0% | U18: Upper 90.0%
A19: =[3]Data!J19 -> 291.05761 | B19: =[3]Data!K19 -> 19.701526 | C19: =[3]Data!N19 -> 0.1771287 | M19: Intercept | N19: 0.086092202 | O19: 0.025632715 | P19: 3.3586844 | Q19: 0.0011203812 | R19: 0.035218358 | S19: 0.13696605 | T19: 0.043523577 | U19: 0.12866083
A20: =[3]Data!J20 -> 696.8107 | B20: =[3]Data!K20 -> 30.212204 | C20: =[3]Data!N20 -> 0.28515499 | M20: Sales | N20: 0.00018774323 | O20: 3.1179521e-05 | P20: 6.0213635 | Q20: 3.0905071e-08 | R20: 0.00012586051 | S20: 0.00024962594 | T20: 0.00013596294 | U20: 0.00023952351
A21: =[3]Data!J21 -> 551.575 | B21: =[3]Data!K21 -> 42.328425 | C21: =[3]Data!N21 -> 0.34135722 | M21: Quantity Sold | N21: 0.0031779896 | O21: 0.00072684022 | P21: 4.3723359 | Q21: 3.0910814e-05 | R21: 0.001735413 | S21: 0.0046205662 | T21: 0.0019709154 | U21: 0.0043850638
A22: =[3]Data!J22 -> 495.58883 | B22: =[3]Data!K22 -> 25.761026 | C22: =[3]Data!N22 -> 0.25651376
A23: =[3]Data!J23 -> 252.88053 | B23: =[3]Data!K23 -> 32.124851 | C23: =[3]Data!N23 -> 0.14962905
A24: =[3]Data!J24 -> 294.05947 | B24: =[3]Data!K24 -> 42.450393 | C24: =[3]Data!N24 -> 0.18294063 | M24: Profit Margin | N24: = | O24: =N19 -> 0.086092202 | P24: + | Q24: Sales | R24: * | S24: =N20 -> 0.00018774323 | T24: + | U24: Qs | V24: * | W24: =N21 -> 0.0031779896
A25: =[3]Data!J25 -> 521.92242 | B25: =[3]Data!K25 -> 27.640041 | C25: =[3]Data!N25 -> 0.2736767 | M25: =O25+(Q25*S25)+(U25*W25) -> 0.28654081 | O25: =O24 -> 0.086092202 | Q25: 526 | S25: =S24 -> 0.00018774323 | U25: 32 | W25: =W24 -> 0.0031779896
A26: =[3]Data!J26 -> 415.68002 | B26: =[3]Data!K26 -> 23.105048 | C26: =[3]Data!N26 -> 0.22479924
A27: =[3]Data!J27 -> 463.17255 | B27: =[3]Data!K27 -> 25.06958 | C27: =[3]Data!N27 -> 0.25128815
A28: =[3]Data!J28 -> 720.9101 | B28: =[3]Data!K28 -> 37.446775 | C28: =[3]Data!N28 -> 0.34981256
A29: =[3]Data!J29 -> 830.1337 | B29: =[3]Data!K29 -> 34.093862 | C29: =[3]Data!N29 -> 0.2756871
A30: =[3]Data!J30 -> 573.45235 | B30: =[3]Data!K30 -> 31.988254 | C30: =[3]Data!N30 -> 0.29108656
A31: =[3]Data!J31 -> 473.55217 | B31: =[3]Data!K31 -> 25.403001 | C31: =[3]Data!N31 -> 0.25301998
A32: =[3]Data!J32 -> 545.77267 | B32: =[3]Data!K32 -> 42.957475 | C32: =[3]Data!N32 -> 0.28087419
A33: =[3]Data!J33 -> 375.22752 | B33: =[3]Data!K33 -> 32.509504 | C33: =[3]Data!N33 -> 0.29589157
A34: =[3]Data!J34 -> 610.02358 | B34: =[3]Data!K34 -> 37.920199 | C34: =[3]Data!N34 -> 0.35610875
A35: =[3]Data!J35 -> 830.1337 | B35: =[3]Data!K35 -> 23.331898 | C35: =[3]Data!N35 -> 0.37607346
A36: =[3]Data!J36 -> 307.91532 | B36: =[3]Data!K36 -> 28.213311 | C36: =[3]Data!N36 -> 0.18955233
A37: =[3]Data!J37 -> 557.79181 | B37: =[3]Data!K37 -> 29.545056 | C37: =[3]Data!N37 -> 0.28130963
... A101: =[3]Data!J101 -> 419.38043 | B101: =[3]Data!K101 -> 36.139059 | C101: =[3]Data!N101 -> 0.23183288

Sheet t-test
A1: {=Data!B1:B101} -> Gender | B1: {=Data!N1:N101} -> Profit Margin
A2: Female | B2: 0.220737 | D2: Is there any significant difference in average profit margin between male and female customers? | N2: Female | O2: Male
A3: Female | B3: 0.30629011 | N3: 0.220737 | O3: 0.28936177 | Q3: t-Test: Two-Sample Assuming Equal Variances
A4: Female | B4: 0.2921224 | D4: Sig level: | E4: 0.05 | N4: 0.30629011 | O4: 0.25439927
A5: Female | B5: 0.21104944 | N5: 0.2921224 | O5: 0.21021883 | R5: Female | S5: Male
A6: Female | B6: 0.22284298 | N6: 0.21104944 | O6: 0.31072854 | Q6: Mean | R6: 0.28658186 | S6: 0.28658186
A7: Female | B7: 0.3515502 | N7: 0.22284298 | O7: 0.27918052 | Q7: Variance | R7: 0.0045651858 | S7: 0.0032686547
A8: Female | B8: 0.26802295 | N8: 0.3515502 | O8: 0.29895453 | Q8: Observations | R8: 50 | S8: 50
A9: Female | B9: 0.40987566 | N9: 0.26802295 | O9: 0.25465479 | Q9: Pooled Variance | R9: 0.0039169202
A10: Female | B10: 0.1771287 | N10: 0.40987566 | O10: 0.35719493 | Q10: Hypothesized Mean Difference | R10: 0
A11: Female | B11: 0.34135722 | N11: 0.1771287 | O11: 0.31830109 | Q11: df | R11: 98
A12: Female | B12: 0.14962905 | N12: 0.34135722 | O12: 0.28515499 | Q12: t Stat | R12: -0.047672036
A13: Female | B13: 0.2736767 | N13: 0.14962905 | O13: 0.25651376 | Q13: P(T<=t) one-tail | R13: 0.48103732
A14: Female | B14: 0.25128815 | N14: 0.2736767 | O14: 0.18294063 | Q14: t Critical one-tail | R14: 1.6605512
A15: Female | B15: 0.2756871 | N15: 0.25128815 | O15: 0.22479924 | Q15: P(T<=t) two-tail | R15: 0.96207464
A16: Female | B16: 0.25301998 | N16: 0.2756871 | O16: 0.34981256 | Q16: t Critical two-tail | R16: 1.9844675
A17: Female | B17: 0.29589157 | N17: 0.25301998 | O17: 0.29108656
A18: Female | B18: 0.37607346 | N18: 0.29589157 | O18: 0.28087419
A19: Female | B19: 0.28130963 | N19: 0.37607346 | O19: 0.35610875
A20: Female | B20: 0.35867859 | N20: 0.28130963 | O20: 0.18955233 | Q20: P is 0.96 higher than 0.05 the null hypo is accepted and alternative is rejected; there is no significance difference
A21: Female | B21: 0.34656381 | N21: 0.35867859 | O21: 0.24905707
A22: Female | B22: 0.45044823 | N22: 0.34656381 | O22: 0.3233103
A23: Female | B23: 0.23379176 | N23: 0.45044823 | O23: 0.41054205
A24: Female | B24: 0.29718857 | N24: 0.23379176 | O24: 0.26813507
A25: Female | B25: 0.34625154 | N25: 0.29718857 | O25: 0.36212322
A26: Female | B26: 0.25403672 | N26: 0.34625154 | O26: 0.28336943
A27: Female | B27: 0.26525405 | N27: 0.25403672 | O27: 0.30257537
A28: Female | B28: 0.3568368 | N28: 0.26525405 | O28: 0.37184959
A29: Female | B29: 0.39777191 | N29: 0.3568368 | O29: 0.28728977
A30: Female | B30: 0.27643788 | N30: 0.39777191 | O30: 0.24060566
A31: Female | B31: 0.3404213 | N31: 0.27643788 | O31: 0.3300623
A32: Female | B32: 0.32266433 | N32: 0.3404213 | O32: 0.27434135
... A52: Male | B52: 0.28936177 | N52: 0.23183288 | O52: 0.26928535
A53: Male | B53: 0.25439927
A54: Male | B54: 0.21021883
A55: Male | B55: 0.31072854
A56: Male | B56: 0.27918052
A57: Male | B57: 0.29895453
A58: Male | B58: 0.25465479
A59: Male | B59: 0.35719493
...

Sheet Descriptive
A1: =Data!J1 -> Sales | B1: =Data!K1 -> Quantity Sold | D1: Sales | F1: Quantity Sold
A2: =Data!J2 -> 886.13398 | B2: =Data!K2 -> 22.670661 | I2: Sales | K2: Quantity Sold
A3: =Data!J3 -> 610.02358 | B3: =Data!K3 -> 22.712923 | D3: Mean | E3: 535.26928 | F3: Mean | G3: 31.559208
A4: =Data!J4 -> 576.61392 | B4: =Data!K4 -> 32.112951 | D4: Standard Error | E4: 15.823718 | F4: Standard Error | G4: 0.67879561 | I4: Mean | J4: 535.26928 | K4: Mean | L4: 31.559208
A5: =Data!J5 -> 372.90517 | B5: =Data!K5 -> 32.509504 | D5: Median | E5: 522.46685 | F5: Median | G5: 32.317177 | I5: Standard Error | J5: 15.823718 | K5: Standard Error | L5: 0.67879561
A6: =Data!J6 -> 413.90525 | B6: =Data!K6 -> 22.800457 | D6: Mode | E6: 619.41734 | F6: Mode | G6: 25.659829 | I6: Median | J6: 522.46685 | K6: Median | L6: 32.317177
A7: =Data!J7 -> 726.81694 | B7: =Data!K7 -> 34.16821 | D7: Standard Deviation | E7: 158.23718 | F7: Standard Deviation | G7: 6.7879561 | I7: Mode | J7: 619.41734 | K7: Mode | L7: 25.659829
A8: =Data!J8 -> 497.81318 | B8: =Data!K8 -> 34.233543 | D8: Sample Variance | E8: 25039.006 | F8: Sample Variance | G8: 46.076348 | I8: Standard Deviation | J8: 158.23718 | K8: Standard Deviation | L8: 6.7879561
A9: =Data!J9 -> 610.02358 | B9: =Data!K9 -> 42.863547 | D9: Kurtosis | E9: -0.1174625 | F9: Kurtosis | G9: -0.84273838 | I9: Sample Variance | J9: 25039.006 | K9: Sample Variance | L9: 46.076348
A10: =Data!J10 -> 291.05761 | B10: =Data!K10 -> 19.701526 | D10: Skewness | E10: 0.23541229 | F10: Skewness | G10: -0.081175098 | I10: Kurtosis | J10: -0.1174625 | K10: Kurtosis | L10: -0.84273838
A11: =Data!J11 -> 551.575 | B11: =Data!K11 -> 42.328425 | D11: Range | E11: 723.41167 | F11: Range | G11: 27.780162 | I11: Skewness | J11: 0.23541229 | K11: Skewness | L11: -0.081175098
A12: =Data!J12 -> 252.88053 | B12: =Data!K12 -> 32.124851 | D12: Minimum | E12: 167.05153 | F12: Minimum | G12: 15.177312 | I12: Range | J12: 723.41167 | K12: Range | L12: 27.780162
A13: =Data!J13 -> 521.92242 | B13: =Data!K13 -> 27.640041 | D13: Maximum | E13: 890.46319 | F13: Maximum | G13: 42.957475 | I13: Minimum | J13: 167.05153 | K13: Minimum | L13: 15.177312
A14: =Data!J14 -> 463.17255 | B14: =Data!K14 -> 25.06958 | D14: Sum | E14: 53526.928 | F14: Sum | G14: 3155.9208 | I14: Maximum | J14: 890.46319 | K14: Maximum | L14: 42.957475
A15: =Data!J15 -> 830.1337 | B15: =Data!K15 -> 34.093862 | D15: Count | E15: 100 | F15: Count | G15: 100 | I15: Sum | J15: 53526.928 | K15: Sum | L15: 3155.9208
A16: =Data!J16 -> 473.55217 | B16: =Data!K16 -> 25.403001 | I16: Count | J16: 100 | K16: Count | L16: 100
A17: =Data!J17 -> 375.22752 | B17: =Data!K17 -> 32.509504
A18: =Data!J18 -> 830.1337 | B18: =Data!K18 -> 23.331898
A19: =Data!J19 -> 557.79181 | B19: =Data!K19 -> 29.545056
A20: =Data!J20 -> 734.5436 | B20: =Data!K20 -> 36.148044
A21: =Data!J21 -> 708.16776 | B21: =Data!K21 -> 36.462645
A22: =Data!J22 -> 890.46319 | B22: =Data!K22 -> 28.856358
A23: =Data!J23 -> 421.88564 | B23: =Data!K23 -> 24.258495
A24: =Data!J24 -> 596.96016 | B24: =Data!K24 -> 32.640045
A25: =Data!J25 -> 696.8107 | B25: =Data!K25 -> 36.329472
A26: =Data!J26 -> 484.28885 | B26: =Data!K26 -> 22.670661
A27: =Data!J27 -> 496.06703 | B27: =Data!K27 -> 26.679784
A28: =Data!J28 -> 523.01127 | B28: =Data!K28 -> 21.01494
... A101: =Data!J101 -> 504.65459 | B101: =Data!K101 -> 25.659829
